Workbook

Sheet Resumen
A1: PROYECCIÓN DE CAJA 2026 – 2034
A2: Unidad: miles de soles (S/000). Ejemplo: 140,028 equivale a S/ 140.028 millones. Todo se recalcula desde Supuestos, Inversiones, Headcount, Deuda y Motor Semanal.
A4: Resultados clave | C4: ='Flujo Anual'!C4 -> 2026 | D4: ='Flujo Anual'!D4 -> 2027 | E4: ='Flujo Anual'!E4 -> 2028 | F4: ='Flujo Anual'!F4 -> 2029 | G4: ='Flujo Anual'!G4 -> 2030 | H4: ='Flujo Anual'!H4 -> 2031 | I4: ='Flujo Anual'!I4 -> 2032 | J4: ='Flujo Anual'!J4 -> 2033 | K4: ='Flujo Anual'!K4 -> 2034 | L4: Total
A5: Ventas del año | C5: ='Flujo Anual'!C7 -> 140027.51 | D5: ='Flujo Anual'!D7 -> 170243.83 | E5: ='Flujo Anual'!E7 -> 199056.11 | F5: ='Flujo Anual'!F7 -> 231900.37 | G5: ='Flujo Anual'!G7 -> 269004.43 | H5: ='Flujo Anual'!H7 -> 310700.11 | I5: ='Flujo Anual'!I7 -> 354198.13 | J5: ='Flujo Anual'!J7 -> 403785.87 | ... L5: ='Flujo Anual'!L7 -> 2539232.3
A6: Total ingresos operativos | C6: ='Flujo Anual'!C13 -> 135832.09 | D6: ='Flujo Anual'!D13 -> 167690.27 | E6: ='Flujo Anual'!E13 -> 196375.92 | F6: ='Flujo Anual'!F13 -> 229024.28 | G6: ='Flujo Anual'!G13 -> 265954.05 | H6: ='Flujo Anual'!H13 -> 307507.3 | I6: ='Flujo Anual'!I13 -> 350980.96 | J6: ='Flujo Anual'!J13 -> 400522.08 | ... L6: ='Flujo Anual'!L13 -> 2510942.4
A7: Total egresos operativos | C7: ='Flujo Anual'!C23 -> 142200.85 | D7: ='Flujo Anual'!D23 -> 170708.59 | E7: ='Flujo Anual'!E23 -> 197120.67 | F7: ='Flujo Anual'!F23 -> 226509.95 | G7: ='Flujo Anual'!G23 -> 259338.44 | H7: ='Flujo Anual'!H23 -> 295434.53 | I7: ='Flujo Anual'!I23 -> 333273.36 | J7: ='Flujo Anual'!J23 -> 376121.75 | ... L7: ='Flujo Anual'!L23 -> 2425882
A8: Flujo operativo | C8: ='Flujo Anual'!C25 -> -6368.762 | D8: ='Flujo Anual'!D25 -> -3018.3271 | E8: ='Flujo Anual'!E25 -> -744.74482 | F8: ='Flujo Anual'!F25 -> 2514.3326 | G8: ='Flujo Anual'!G25 -> 6615.6132 | H8: ='Flujo Anual'!H25 -> 12072.769 | I8: ='Flujo Anual'!I25 -> 17707.596 | J8: ='Flujo Anual'!J25 -> 24400.327 | ... L8: ='Flujo Anual'!L25 -> 85060.389
A9: Inversiones | C9: ='Flujo Anual'!C29 -> 2070 | D9: ='Flujo Anual'!D29 -> 1440 | E9: ='Flujo Anual'!E29 -> 570 | F9: ='Flujo Anual'!F29 -> 0 | G9: ='Flujo Anual'!G29 -> 200 | H9: ='Flujo Anual'!H29 -> 1050 | I9: ='Flujo Anual'!I29 -> 0 | J9: ='Flujo Anual'!J29 -> 0 | ... L9: ='Flujo Anual'!L29 -> 5330
A10: Servicio de deuda | C10: ='Flujo Anual'!C40 -> 2854.3688 | D10: ='Flujo Anual'!D40 -> 4702.9933 | E10: ='Flujo Anual'!E40 -> 5088.0194 | F10: ='Flujo Anual'!F40 -> 4923.3061 | G10: ='Flujo Anual'!G40 -> 2017.5632 | H10: ='Flujo Anual'!H40 -> 2463.825 | I10: ='Flujo Anual'!I40 -> 2747.2531 | J10: ='Flujo Anual'!J40 -> 2991.1252 | ... L10: ='Flujo Anual'!L40 -> 30756.229
A11: Desembolso de préstamos y leasing | C11: ='Flujo Anual'!C32 -> 2070 | D11: ='Flujo Anual'!D32 -> 1440 | E11: ='Flujo Anual'!E32 -> 570 | F11: ='Flujo Anual'!F32 -> 0 | G11: ='Flujo Anual'!G32 -> 200 | H11: ='Flujo Anual'!H32 -> 1050 | I11: ='Flujo Anual'!I32 -> 0 | J11: ='Flujo Anual'!J32 -> 0 | ... L11: ='Flujo Anual'!L32 -> 5330
A12: Flujo neto del año | C12: ='Flujo Anual'!C43 -> -9223.1308 | D12: ='Flujo Anual'!D43 -> -7721.3205 | E12: ='Flujo Anual'!E43 -> -5832.7642 | F12: ='Flujo Anual'!F43 -> -2408.9736 | G12: ='Flujo Anual'!G43 -> 4598.05 | H12: ='Flujo Anual'!H43 -> 9608.9438 | I12: ='Flujo Anual'!I43 -> 14960.343 | J12: ='Flujo Anual'!J43 -> 21409.202 | ... L12: ='Flujo Anual'!L43 -> 54304.159
A13: Caja final | C13: ='Flujo Anual'!C47 -> -9223.1308 | D13: ='Flujo Anual'!D47 -> -16944.451 | E13: ='Flujo Anual'!E47 -> -22777.215 | F13: ='Flujo Anual'!F47 -> -25186.189 | G13: ='Flujo Anual'!G47 -> -20588.139 | H13: ='Flujo Anual'!H47 -> -10979.195 | I13: ='Flujo Anual'!I47 -> 3981.1473 | J13: ='Flujo Anual'!J47 -> 25390.349 | ... L13: ='Flujo Anual'!L47 -> 54304.159
A14: Caja mínima de un mes del año | C14: ='Flujo Anual'!C48 -> -9275.4056 | D14: ='Flujo Anual'!D48 -> -18263.212 | E14: ='Flujo Anual'!E48 -> -25394.365 | F14: ='Flujo Anual'!F48 -> -30035.422 | G14: ='Flujo Anual'!G48 -> -29115.047 | H14: ='Flujo Anual'!H48 -> -22988.756 | I14: ='Flujo Anual'!I48 -> -11360.064 | J14: ='Flujo Anual'!J48 -> 2748.4621 | ... L14: ='Flujo Anual'!L48 -> -30035.422
A33: CÓMO ESTÁ ORDENADO EL ARCHIVO
A34: Resumen | B34: Esta hoja: resultados clave, guía y puntos a revisar.
A35: Flujo Anual | B35: El flujo de caja 2026-2034, un año por columna (suma del mensual).
A36: Flujo Mensual | B36: Mismo flujo mes a mes (108 meses). Aquí ves cuándo la caja se aprieta.
A37: Supuestos | B37: TODOS los datos de entrada: ventas, compras, gastos, financiamientos, movimientos manuales.
A38: Inversiones | B38: Inversiones y alquileres nuevos por año (en S/).
A39: Headcount | B39: Personal por año; define cuánto crece la planilla.
A40: Deuda Mensual | B40: Deuda mes a mes: cuotas de bancos + tabla de amortización de cada nuevo préstamo/leasing.
A41: Deuda Bancos | B41: Cronograma de cuotas que te entregó el banco (solo datos).
A42: Motor Semanal | B42: Cálculo semanal de ventas → cobranza. No se edita salvo las ventas semanales de 2026.
A43: Arch_… | B43: Hojas antiguas que ya no alimentan el flujo (se dejan por si las necesitas).
A45: COLORES
A46: Azul | B46: dato que tú ingresas
A47: Negro | B47: fórmula de la misma hoja
A48: Verde | B48: viene de otra hoja
A49: Fondo amarillo | B49: supuesto clave: revísalo primero
A51: PUNTOS A REVISAR (supuestos míos o vacíos de tu archivo original)
A52: 1. Unidad: tomé "miles de S/" porque la deuda y las inversiones están en soles. Si tu flujo está en miles de US$, avísame.
A53: 2. Otros gastos administrativos y comerciales 2027-2034 = % de ventas de tu cuadro (Supuestos fila 56). Con Supuestos!B22 = 0 quedan en cero.
A54: 3. La tabla de deuda empieza en oct-2026: el pago de cuotas ene-sep 2026 no está en el flujo (solo los 3 pagos CP manuales).
A55: 4. El motor semanal usa siempre la mezcla contado/crédito 2026 (66%/34%) aunque Supuestos tiene una mezcla distinta por año. Afecta solo el calendario de cobro.
A56: 5. No están modelados: IGV de ventas, renta 1.5%, rebates e intereses de préstamos CP. Protestos e incobrables sí siguen tu cuadro de %.
A57: 6. Caja inicial ene-2026 = 0 (como tu flujo original). Cámbiala en Supuestos!B24.
A58: 7. Financiamiento: camiones = leasing, mejoras/racks/mobiliario = mediano plazo; los montos salen de Inversiones. El desembolso entra en el mes de la 1ª cuota (Supuestos!I35:I40).
A59: 8. Inversiones se pagan en un solo mes por año (Supuestos fila 20); alquileres nuevos se reparten en 12 meses.
A60: 9. Compras nov y dic-2034 usan ventas 2035 estimadas con +14% (Supuestos!B21), porque tu modelo termina en 2034.
A61: 10. Inversiones: "Alquiler Máquinas Lima" 2028-29 = 4,500 sin ×12 como las otras sedes; confirma si es mensual.
...

Sheet Flujo Anual
A1: FLUJO DE CAJA ANUAL 2026 – 2034
A2: Unidad: miles de soles (S/000). Ejemplo: 140,028 equivale a S/ 140.028 millones. Egresos en positivo (se restan); cada año suma 12 meses de Flujo Mensual.
A4: Año | C4: =Supuestos!B1 -> 2026 | D4: =Supuestos!C1 -> 2027 | E4: =Supuestos!D1 -> 2028 | F4: =Supuestos!E1 -> 2029 | G4: =Supuestos!F1 -> 2030 | H4: =Supuestos!G1 -> 2031 | I4: =Supuestos!H1 -> 2032 | J4: =Supuestos!I1 -> 2033 | K4: =Supuestos!J1 -> 2034 | L4: Total
A6: 1. INGRESOS OPERATIVOS
A7: Ventas del año (referencia, no es caja) | C7: =SUM('Flujo Mensual'!C10:N10) -> 140027.51 | D7: =SUM('Flujo Mensual'!O10:Z10) -> 170243.83 | E7: =SUM('Flujo Mensual'!AA10:AL10) -> 199056.11 | F7: =SUM('Flujo Mensual'!AM10:AX10) -> 231900.37 | G7: =SUM('Flujo Mensual'!AY10:BJ10) -> 269004.43 | H7: =SUM('Flujo Mensual'!BK10:BV10) -> 310700.11 | I7: =SUM('Flujo Mensual'!BW10:CH10) -> 354198.13 | J7: =SUM('Flujo Mensual'!CI10:CT10) -> 403785.87 | K7: =SUM('Flujo Mensual'!CU10:DF10) -> 460315.89 | L7: =SUM(C7:K7) -> 2539232.3
A8: Crecimiento de ventas | D8: =D7/C7-1 -> 0.21578844 | E8: =E7/D7-1 -> 0.16924125 | F8: =F7/E7-1 -> 0.165 | G8: =G7/F7-1 -> 0.16 | H8: =H7/G7-1 -> 0.155 | I8: =I7/H7-1 -> 0.14 | J8: =J7/I7-1 -> 0.14 | K8: =K7/J7-1 -> 0.14
A9: Cobro de ventas al contado | C9: =SUM('Flujo Mensual'!C11:N11) -> 87876.291 | D9: =SUM('Flujo Mensual'!O11:Z11) -> 112233.23 | E9: =SUM('Flujo Mensual'!AA11:AL11) -> 131324.36 | F9: =SUM('Flujo Mensual'!AM11:AX11) -> 152994.42 | G9: =SUM('Flujo Mensual'!AY11:BJ11) -> 177475.35 | H9: =SUM('Flujo Mensual'!BK11:BV11) -> 204986.14 | I9: =SUM('Flujo Mensual'!BW11:CH11) -> 233691.54 | J9: =SUM('Flujo Mensual'!CI11:CT11) -> 266408.36 | K9: =SUM('Flujo Mensual'!CU11:DF11) -> 303705.53 | L9: =SUM(C9:K9) -> 1670695.2
A10: Cobro por descuento de letras | C10: =SUM('Flujo Mensual'!C12:N12) -> 23670.8 | D10: =SUM('Flujo Mensual'!O12:Z12) -> 26616.342 | E10: =SUM('Flujo Mensual'!AA12:AL12) -> 31090.767 | F10: =SUM('Flujo Mensual'!AM12:AX12) -> 36221.967 | G10: =SUM('Flujo Mensual'!AY12:BJ12) -> 42018.914 | H10: =SUM('Flujo Mensual'!BK12:BV12) -> 48533.513 | I10: =SUM('Flujo Mensual'!BW12:CH12) -> 55334.01 | J10: =SUM('Flujo Mensual'!CI12:CT12) -> 63080.771 | K10: =SUM('Flujo Mensual'!CU12:DF12) -> 71912.079 | L10: =SUM(C10:K10) -> 398479.16
A11: Cobranza libre / cartera | C11: =SUM('Flujo Mensual'!C13:N13) -> 26105.359 | D11: =SUM('Flujo Mensual'!O13:Z13) -> 30883.62 | E11: =SUM('Flujo Mensual'!AA13:AL13) -> 36150.418 | F11: =SUM('Flujo Mensual'!AM13:AX13) -> 42126.893 | G11: =SUM('Flujo Mensual'!AY13:BJ13) -> 48880.832 | H11: =SUM('Flujo Mensual'!BK13:BV13) -> 56473.248 | I11: =SUM('Flujo Mensual'!BW13:CH13) -> 64434.79 | J11: =SUM('Flujo Mensual'!CI13:CT13) -> 73455.66 | K11: =SUM('Flujo Mensual'!CU13:DF13) -> 83739.452 | L11: =SUM(C11:K11) -> 462250.27
A12: (−) Incobrables | C12: =SUM('Flujo Mensual'!C14:N14) -> -1820.3577 | D12: =SUM('Flujo Mensual'!O14:Z14) -> -2042.926 | E12: =SUM('Flujo Mensual'!AA14:AL14) -> -2189.6172 | F12: =SUM('Flujo Mensual'!AM14:AX14) -> -2319.0037 | G12: =SUM('Flujo Mensual'!AY14:BJ14) -> -2421.0399 | H12: =SUM('Flujo Mensual'!BK14:BV14) -> -2485.6009 | I12: =SUM('Flujo Mensual'!BW14:CH14) -> -2479.3869 | J12: =SUM('Flujo Mensual'!CI14:CT14) -> -2422.7152 | K12: =SUM('Flujo Mensual'!CU14:DF14) -> -2301.5795 | L12: =SUM(C12:K12) -> -20482.227
A13: TOTAL INGRESOS OPERATIVOS | C13: =SUM('Flujo Mensual'!C15:N15) -> 135832.09 | D13: =SUM('Flujo Mensual'!O15:Z15) -> 167690.27 | E13: =SUM('Flujo Mensual'!AA15:AL15) -> 196375.92 | F13: =SUM('Flujo Mensual'!AM15:AX15) -> 229024.28 | G13: =SUM('Flujo Mensual'!AY15:BJ15) -> 265954.05 | H13: =SUM('Flujo Mensual'!BK15:BV15) -> 307507.3 | I13: =SUM('Flujo Mensual'!BW15:CH15) -> 350980.96 | J13: =SUM('Flujo Mensual'!CI15:CT15) -> 400522.08 | K13: =SUM('Flujo Mensual'!CU15:DF15) -> 457055.48 | L13: =SUM(C13:K13) -> 2510942.4
A15: 2. EGRESOS OPERATIVOS
A16: Compras de mercadería | C16: =SUM('Flujo Mensual'!C18:N18) -> 124789.37 | D16: =SUM('Flujo Mensual'!O18:Z18) -> 150392.29 | E16: =SUM('Flujo Mensual'!AA18:AL18) -> 174155.78 | F16: =SUM('Flujo Mensual'!AM18:AX18) -> 200815.17 | G16: =SUM('Flujo Mensual'!AY18:BJ18) -> 230668.73 | H16: =SUM('Flujo Mensual'!BK18:BV18) -> 264023.06 | I16: =SUM('Flujo Mensual'!BW18:CH18) -> 298975.42 | J16: =SUM('Flujo Mensual'!CI18:CT18) -> 338539.93 | K16: =SUM('Flujo Mensual'!CU18:DF18) -> 383800.08 | L16: =SUM(C16:K16) -> 2166159.8
A17: Planilla administrativa | C17: =SUM('Flujo Mensual'!C19:N19) -> 2008.7878 | D17: =SUM('Flujo Mensual'!O19:Z19) -> 2371.6035 | E17: =SUM('Flujo Mensual'!AA19:AL19) -> 2574.8838 | F17: =SUM('Flujo Mensual'!AM19:AX19) -> 2642.6439 | G17: =SUM('Flujo Mensual'!AY19:BJ19) -> 2845.9242 | H17: =SUM('Flujo Mensual'!BK19:BV19) -> 2913.6843 | I17: =SUM('Flujo Mensual'!BW19:CH19) -> 3184.7247 | J17: =SUM('Flujo Mensual'!CI19:CT19) -> 3388.005 | K17: =SUM('Flujo Mensual'!CU19:DF19) -> 3523.5252 | L17: =SUM(C17:K17) -> 25453.782
A18: Otros gastos administrativos | C18: =SUM('Flujo Mensual'!C20:N20) -> 2979.6605 | D18: =SUM('Flujo Mensual'!O20:Z20) -> 3404.8766 | E18: =SUM('Flujo Mensual'!AA20:AL20) -> 3583.01 | F18: =SUM('Flujo Mensual'!AM20:AX20) -> 4174.2066 | G18: =SUM('Flujo Mensual'!AY20:BJ20) -> 4842.0797 | H18: =SUM('Flujo Mensual'!BK20:BV20) -> 5592.6021 | I18: =SUM('Flujo Mensual'!BW20:CH20) -> 6021.3682 | J18: =SUM('Flujo Mensual'!CI20:CT20) -> 6864.3598 | K18: =SUM('Flujo Mensual'!CU20:DF20) -> 7825.3701 | L18: =SUM(C18:K18) -> 45287.534
A19: Planilla comercial | C19: =SUM('Flujo Mensual'!C21:N21) -> 5264.2599 | D19: =SUM('Flujo Mensual'!O21:Z21) -> 6089.8718 | E19: =SUM('Flujo Mensual'!AA21:AL21) -> 6983.7979 | F19: =SUM('Flujo Mensual'!AM21:AX21) -> 7710.1129 | G19: =SUM('Flujo Mensual'!AY21:BJ21) -> 8324.6871 | H19: =SUM('Flujo Mensual'!BK21:BV21) -> 8939.2613 | I19: =SUM('Flujo Mensual'!BW21:CH21) -> 9609.7059 | J19: =SUM('Flujo Mensual'!CI21:CT21) -> 10168.41 | K19: =SUM('Flujo Mensual'!CU21:DF21) -> 11006.465 | L19: =SUM(C19:K19) -> 74096.572
A20: Otros gastos comerciales | C20: =SUM('Flujo Mensual'!C22:N22) -> 6598.6694 | D20: =SUM('Flujo Mensual'!O22:Z22) -> 7660.9724 | E20: =SUM('Flujo Mensual'!AA22:AL22) -> 8758.4689 | F20: =SUM('Flujo Mensual'!AM22:AX22) -> 9971.7159 | G20: =SUM('Flujo Mensual'!AY22:BJ22) -> 11029.182 | H20: =SUM('Flujo Mensual'!BK22:BV22) -> 12117.304 | I20: =SUM('Flujo Mensual'!BW22:CH22) -> 13459.529 | J20: =SUM('Flujo Mensual'!CI22:CT22) -> 14940.077 | K20: =SUM('Flujo Mensual'!CU22:DF22) -> 16571.372 | L20: =SUM(C20:K20) -> 101107.29
A21: Protestos | C21: =SUM('Flujo Mensual'!C23:N23) -> 560.11005 | D21: =SUM('Flujo Mensual'!O23:Z23) -> 680.97533 | E21: =SUM('Flujo Mensual'!AA23:AL23) -> 796.22444 | F21: =SUM('Flujo Mensual'!AM23:AX23) -> 927.60148 | G21: =SUM('Flujo Mensual'!AY23:BJ23) -> 1076.0177 | H21: =SUM('Flujo Mensual'!BK23:BV23) -> 1242.8005 | I21: =SUM('Flujo Mensual'!BW23:CH23) -> 1416.7925 | J21: =SUM('Flujo Mensual'!CI23:CT23) -> 1615.1435 | K21: =SUM('Flujo Mensual'!CU23:DF23) -> 1841.2636 | L21: =SUM(C21:K21) -> 10156.929
A22: Alquileres nuevas sedes y máquinas | C22: =SUM('Flujo Mensual'!C24:N24) -> 0 | D22: =SUM('Flujo Mensual'!O24:Z24) -> 108 | E22: =SUM('Flujo Mensual'!AA24:AL24) -> 268.5 | F22: =SUM('Flujo Mensual'!AM24:AX24) -> 268.5 | G22: =SUM('Flujo Mensual'!AY24:BJ24) -> 551.82 | H22: =SUM('Flujo Mensual'!BK24:BV24) -> 605.82 | I22: =SUM('Flujo Mensual'!BW24:CH24) -> 605.82 | J22: =SUM('Flujo Mensual'!CI24:CT24) -> 605.82 | K22: =SUM('Flujo Mensual'!CU24:DF24) -> 605.82 | L22: =SUM(C22:K22) -> 3620.1
A23: TOTAL EGRESOS OPERATIVOS | C23: =SUM('Flujo Mensual'!C25:N25) -> 142200.85 | D23: =SUM('Flujo Mensual'!O25:Z25) -> 170708.59 | E23: =SUM('Flujo Mensual'!AA25:AL25) -> 197120.67 | F23: =SUM('Flujo Mensual'!AM25:AX25) -> 226509.95 | G23: =SUM('Flujo Mensual'!AY25:BJ25) -> 259338.44 | H23: =SUM('Flujo Mensual'!BK25:BV25) -> 295434.53 | I23: =SUM('Flujo Mensual'!BW25:CH25) -> 333273.36 | J23: =SUM('Flujo Mensual'!CI25:CT25) -> 376121.75 | K23: =SUM('Flujo Mensual'!CU25:DF25) -> 425173.9 | L23: =SUM(C23:K23) -> 2425882
A25: 3. FLUJO OPERATIVO (1 − 2) | C25: =SUM('Flujo Mensual'!C27:N27) -> -6368.762 | D25: =SUM('Flujo Mensual'!O27:Z27) -> -3018.3271 | E25: =SUM('Flujo Mensual'!AA27:AL27) -> -744.74482 | F25: =SUM('Flujo Mensual'!AM27:AX27) -> 2514.3326 | G25: =SUM('Flujo Mensual'!AY27:BJ27) -> 6615.6132 | H25: =SUM('Flujo Mensual'!BK27:BV27) -> 12072.769 | I25: =SUM('Flujo Mensual'!BW27:CH27) -> 17707.596 | J25: =SUM('Flujo Mensual'!CI27:CT27) -> 24400.327 | K25: =SUM('Flujo Mensual'!CU27:DF27) -> 31881.585 | L25: =SUM(C25:K25) -> 85060.389
A26: % sobre ingresos | C26: =IF(C13=0,0,C25/C13) -> -0.04688702 | D26: =IF(D13=0,0,D25/D13) -> -0.017999417 | E26: =IF(E13=0,0,E25/E13) -> -0.0037924446 | F26: =IF(F13=0,0,F25/F13) -> 0.010978454 | G26: =IF(G13=0,0,G25/G13) -> 0.024875023 | H26: =IF(H13=0,0,H25/H13) -> 0.039260105 | I26: =IF(I13=0,0,I25/I13) -> 0.050451728 | J26: =IF(J13=0,0,J25/J13) -> 0.060921304 | ... L26: =IF(L13=0,0,L25/L13) -> 0.033875882
A28: 4. INVERSIONES
A29: Inversión en activos | C29: =SUM('Flujo Mensual'!C31:N31) -> 2070 | D29: =SUM('Flujo Mensual'!O31:Z31) -> 1440 | E29: =SUM('Flujo Mensual'!AA31:AL31) -> 570 | F29: =SUM('Flujo Mensual'!AM31:AX31) -> 0 | G29: =SUM('Flujo Mensual'!AY31:BJ31) -> 200 | H29: =SUM('Flujo Mensual'!BK31:BV31) -> 1050 | I29: =SUM('Flujo Mensual'!BW31:CH31) -> 0 | J29: =SUM('Flujo Mensual'!CI31:CT31) -> 0 | K29: =SUM('Flujo Mensual'!CU31:DF31) -> 0 | L29: =SUM(C29:K29) -> 5330
A31: 5. FINANCIAMIENTO
A32: (+) Desembolso de préstamos y leasing | C32: =SUM('Flujo Mensual'!C34:N34) -> 2070 | D32: =SUM('Flujo Mensual'!O34:Z34) -> 1440 | E32: =SUM('Flujo Mensual'!AA34:AL34) -> 570 | F32: =SUM('Flujo Mensual'!AM34:AX34) -> 0 | G32: =SUM('Flujo Mensual'!AY34:BJ34) -> 200 | H32: =SUM('Flujo Mensual'!BK34:BV34) -> 1050 | I32: =SUM('Flujo Mensual'!BW34:CH34) -> 0 | J32: =SUM('Flujo Mensual'!CI34:CT34) -> 0 | K32: =SUM('Flujo Mensual'!CU34:DF34) -> 0 | L32: =SUM(C32:K32) -> 5330
A33: (−) Principal mediano plazo | C33: =SUM('Flujo Mensual'!C35:N35) -> 475.45054 | D33: =SUM('Flujo Mensual'!O35:Z35) -> 2563.3155 | E33: =SUM('Flujo Mensual'!AA35:AL35) -> 2962.7569 | F33: =SUM('Flujo Mensual'!AM35:AX35) -> 2967.5417 | G33: =SUM('Flujo Mensual'!AY35:BJ35) -> 265.20047 | H33: =SUM('Flujo Mensual'!BK35:BV35) -> 66.565056 | I33: =SUM('Flujo Mensual'!BW35:CH35) -> 71.22461 | J33: =SUM('Flujo Mensual'!CI35:CT35) -> 0 | K33: =SUM('Flujo Mensual'!CU35:DF35) -> 0 | L33: =SUM(C33:K33) -> 9372.0547
A34: (−) Principal leasing | C34: =SUM('Flujo Mensual'!C36:N36) -> 66.548402 | D34: =SUM('Flujo Mensual'!O36:Z36) -> 387.27179 | E34: =SUM('Flujo Mensual'!AA36:AL36) -> 404.00917 | F34: =SUM('Flujo Mensual'!AM36:AX36) -> 313.35128 | G34: =SUM('Flujo Mensual'!AY36:BJ36) -> 0 | H34: =SUM('Flujo Mensual'!BK36:BV36) -> 326.60425 | I34: =SUM('Flujo Mensual'!BW36:CH36) -> 349.46655 | J34: =SUM('Flujo Mensual'!CI36:CT36) -> 373.9292 | K34: =SUM('Flujo Mensual'!CU36:DF36) -> 0 | L34: =SUM(C34:K34) -> 2221.1806
A35: (−) Intereses mediano plazo | C35: =SUM('Flujo Mensual'!C37:N37) -> 146.41171 | D35: =SUM('Flujo Mensual'!O37:Z37) -> 581.57036 | E35: =SUM('Flujo Mensual'!AA37:AL37) -> 392.65653 | F35: =SUM('Flujo Mensual'!AM37:AX37) -> 138.72505 | G35: =SUM('Flujo Mensual'!AY37:BJ37) -> 19.196368 | H35: =SUM('Flujo Mensual'!BK37:BV37) -> 7.3042527 | I35: =SUM('Flujo Mensual'!BW37:CH37) -> 2.6446988 | J35: =SUM('Flujo Mensual'!CI37:CT37) -> 0 | K35: =SUM('Flujo Mensual'!CU37:DF37) -> 0 | L35: =SUM(C35:K35) -> 1288.509
A36: (−) Intereses leasing | C36: =SUM('Flujo Mensual'!C38:N38) -> 13.753993 | D36: =SUM('Flujo Mensual'!O38:Z38) -> 63.209087 | E36: =SUM('Flujo Mensual'!AA38:AL38) -> 36.027265 | F36: =SUM('Flujo Mensual'!AM38:AX38) -> 9.8269438 | G36: =SUM('Flujo Mensual'!AY38:BJ38) -> 0 | H36: =SUM('Flujo Mensual'!BK38:BV38) -> 61.209624 | I36: =SUM('Flujo Mensual'!BW38:CH38) -> 38.347327 | J36: =SUM('Flujo Mensual'!CI38:CT38) -> 13.884669 | K36: =SUM('Flujo Mensual'!CU38:DF38) -> 0 | L36: =SUM(C36:K36) -> 236.25891
A37: (−) IGV y otros cargos de cuotas | C37: =SUM('Flujo Mensual'!C39:N39) -> 2.82003 | D37: =SUM('Flujo Mensual'!O39:Z39) -> 11.28012 | E37: =SUM('Flujo Mensual'!AA39:AL39) -> 9.40011 | F37: =SUM('Flujo Mensual'!AM39:AX39) -> 0 | G37: =SUM('Flujo Mensual'!AY39:BJ39) -> 0 | H37: =SUM('Flujo Mensual'!BK39:BV39) -> 0 | I37: =SUM('Flujo Mensual'!BW39:CH39) -> 0 | J37: =SUM('Flujo Mensual'!CI39:CT39) -> 0 | K37: =SUM('Flujo Mensual'!CU39:DF39) -> 0 | L37: =SUM(C37:K37) -> 23.50026
A38: (−) Gasto financiero por descuento de letras | C38: =SUM('Flujo Mensual'!C40:N40) -> 949.38412 | D38: =SUM('Flujo Mensual'!O40:Z40) -> 1096.3465 | E38: =SUM('Flujo Mensual'!AA40:AL40) -> 1283.1694 | F38: =SUM('Flujo Mensual'!AM40:AX40) -> 1493.8612 | G38: =SUM('Flujo Mensual'!AY40:BJ40) -> 1733.1663 | H38: =SUM('Flujo Mensual'!BK40:BV40) -> 2002.1418 | I38: =SUM('Flujo Mensual'!BW40:CH40) -> 2285.5699 | J38: =SUM('Flujo Mensual'!CI40:CT40) -> 2603.3114 | K38: =SUM('Flujo Mensual'!CU40:DF40) -> 2967.7749 | L38: =SUM(C38:K38) -> 16414.726
A39: (−) Pagos préstamos CP y otros manuales | C39: =SUM('Flujo Mensual'!C41:N41) -> 1200 | D39: =SUM('Flujo Mensual'!O41:Z41) -> 0 | E39: =SUM('Flujo Mensual'!AA41:AL41) -> 0 | F39: =SUM('Flujo Mensual'!AM41:AX41) -> 0 | G39: =SUM('Flujo Mensual'!AY41:BJ41) -> 0 | H39: =SUM('Flujo Mensual'!BK41:BV41) -> 0 | I39: =SUM('Flujo Mensual'!BW41:CH41) -> 0 | J39: =SUM('Flujo Mensual'!CI41:CT41) -> 0 | K39: =SUM('Flujo Mensual'!CU41:DF41) -> 0 | L39: =SUM(C39:K39) -> 1200
A40: SERVICIO DE DEUDA | C40: =SUM('Flujo Mensual'!C42:N42) -> 2854.3688 | D40: =SUM('Flujo Mensual'!O42:Z42) -> 4702.9933 | E40: =SUM('Flujo Mensual'!AA42:AL42) -> 5088.0194 | F40: =SUM('Flujo Mensual'!AM42:AX42) -> 4923.3061 | G40: =SUM('Flujo Mensual'!AY42:BJ42) -> 2017.5632 | H40: =SUM('Flujo Mensual'!BK42:BV42) -> 2463.825 | I40: =SUM('Flujo Mensual'!BW42:CH42) -> 2747.2531 | J40: =SUM('Flujo Mensual'!CI42:CT42) -> 2991.1252 | K40: =SUM('Flujo Mensual'!CU42:DF42) -> 2967.7749 | L40: =SUM(C40:K40) -> 30756.229
A41: FINANCIAMIENTO NETO (desembolsos − servicio) | C41: =SUM('Flujo Mensual'!C43:N43) -> -784.3688 | D41: =SUM('Flujo Mensual'!O43:Z43) -> -3262.9933 | E41: =SUM('Flujo Mensual'!AA43:AL43) -> -4518.0194 | F41: =SUM('Flujo Mensual'!AM43:AX43) -> -4923.3061 | G41: =SUM('Flujo Mensual'!AY43:BJ43) -> -1817.5632 | H41: =SUM('Flujo Mensual'!BK43:BV43) -> -1413.825 | I41: =SUM('Flujo Mensual'!BW43:CH43) -> -2747.2531 | J41: =SUM('Flujo Mensual'!CI43:CT43) -> -2991.1252 | K41: =SUM('Flujo Mensual'!CU43:DF43) -> -2967.7749 | L41: =SUM(C41:K41) -> -25426.229
A43: 6. FLUJO NETO DEL AÑO (3 − 4 + 5) | C43: =SUM('Flujo Mensual'!C45:N45) -> -9223.1308 | D43: =SUM('Flujo Mensual'!O45:Z45) -> -7721.3205 | E43: =SUM('Flujo Mensual'!AA45:AL45) -> -5832.7642 | F43: =SUM('Flujo Mensual'!AM45:AX45) -> -2408.9736 | G43: =SUM('Flujo Mensual'!AY45:BJ45) -> 4598.05 | H43: =SUM('Flujo Mensual'!BK45:BV45) -> 9608.9438 | I43: =SUM('Flujo Mensual'!BW45:CH45) -> 14960.343 | J43: =SUM('Flujo Mensual'!CI45:CT45) -> 21409.202 | K43: =SUM('Flujo Mensual'!CU45:DF45) -> 28913.81 | L43: =SUM(C43:K43) -> 54304.159
A45: 7. CAJA
A46: Caja inicial | C46: ='Flujo Mensual'!C48 -> 0 | D46: ='Flujo Mensual'!O48 -> -9223.1308 | E46: ='Flujo Mensual'!AA48 -> -16944.451 | F46: ='Flujo Mensual'!AM48 -> -22777.215 | G46: ='Flujo Mensual'!AY48 -> -25186.189 | H46: ='Flujo Mensual'!BK48 -> -20588.139 | I46: ='Flujo Mensual'!BW48 -> -10979.195 | J46: ='Flujo Mensual'!CI48 -> 3981.1473 | K46: ='Flujo Mensual'!CU48 -> 25390.349 | L46: =C46 -> 0
A47: CAJA FINAL | C47: ='Flujo Mensual'!N49 -> -9223.1308 | D47: ='Flujo Mensual'!Z49 -> -16944.451 | E47: ='Flujo Mensual'!AL49 -> -22777.215 | F47: ='Flujo Mensual'!AX49 -> -25186.189 | G47: ='Flujo Mensual'!BJ49 -> -20588.139 | H47: ='Flujo Mensual'!BV49 -> -10979.195 | I47: ='Flujo Mensual'!CH49 -> 3981.1473 | J47: ='Flujo Mensual'!CT49 -> 25390.349 | K47: ='Flujo Mensual'!DF49 -> 54304.159 | L47: =K47 -> 54304.159
A48: Caja mínima de un mes dentro del año | C48: =MIN('Flujo Mensual'!C49:N49) -> -9275.4056 | D48: =MIN('Flujo Mensual'!O49:Z49) -> -18263.212 | E48: =MIN('Flujo Mensual'!AA49:AL49) -> -25394.365 | F48: =MIN('Flujo Mensual'!AM49:AX49) -> -30035.422 | G48: =MIN('Flujo Mensual'!AY49:BJ49) -> -29115.047 | H48: =MIN('Flujo Mensual'!BK49:BV49) -> -22988.756 | I48: =MIN('Flujo Mensual'!BW49:CH49) -> -11360.064 | J48: =MIN('Flujo Mensual'!CI49:CT49) -> 2748.4621 | K48: =MIN('Flujo Mensual'!CU49:DF49) -> 24783.991 | L48: =MIN(C48:K48) -> -30035.422
...

Sheet Flujo Mensual
A1: FLUJO DE CAJA MENSUAL 2026 – 2034
A2: Unidad: miles de soles (S/000). Ejemplo: 11,669 equivale a S/ 11.669 millones. Egresos en positivo (se restan); los cambios se realizan en las hojas de datos.
DG3: Ext. 2035 (solo para compras nov-dic 2034)
A4: Mes | B4: De dónde viene | C4: =DATE(Supuestos!$B$1,1,1) -> 46023 | D4: =EDATE(C4,1) -> 46054 | E4: =EDATE(D4,1) -> 46082 | F4: =EDATE(E4,1) -> 46113 | G4: =EDATE(F4,1) -> 46143 | H4: =EDATE(G4,1) -> 46174 | I4: =EDATE(H4,1) -> 46204 | J4: =EDATE(I4,1) -> 46235 | K4: =EDATE(J4,1) -> 46266 | ... DH4: =EDATE(DG4,1) -> 49341
A5: Año | C5: =YEAR(C4) -> 2026 | D5: =YEAR(D4) -> 2026 | E5: =YEAR(E4) -> 2026 | F5: =YEAR(F4) -> 2026 | G5: =YEAR(G4) -> 2026 | H5: =YEAR(H4) -> 2026 | I5: =YEAR(I4) -> 2026 | J5: =YEAR(J4) -> 2026 | ... DH5: =YEAR(DH4) -> 2035
A6: N° mes | C6: =MONTH(C4) -> 1 | D6: =MONTH(D4) -> 2 | E6: =MONTH(E4) -> 3 | F6: =MONTH(F4) -> 4 | G6: =MONTH(G4) -> 5 | H6: =MONTH(H4) -> 6 | I6: =MONTH(I4) -> 7 | J6: =MONTH(J4) -> 8 | ... DH6: =MONTH(DH4) -> 2
A7: Días del mes | C7: =DAY(EOMONTH(C4,0)) -> 31 | D7: =DAY(EOMONTH(D4,0)) -> 28 | E7: =DAY(EOMONTH(E4,0)) -> 31 | F7: =DAY(EOMONTH(F4,0)) -> 30 | G7: =DAY(EOMONTH(G4,0)) -> 31 | H7: =DAY(EOMONTH(H4,0)) -> 30 | I7: =DAY(EOMONTH(I4,0)) -> 31 | J7: =DAY(EOMONTH(J4,0)) -> 31 | ... DH7: =DAY(EOMONTH(DH4,0)) -> 28
A9: 1. INGRESOS OPERATIVOS
A10: Ventas del mes (referencia, no es caja) | B10: Motor Semanal fila 9 | C10: =SUM('Motor Semanal'!B9:F9) -> 12462.316 | D10: =SUM('Motor Semanal'!G9:J9) -> 10499.207 | E10: =SUM('Motor Semanal'!K9:O9) -> 11314.833 | F10: =SUM('Motor Semanal'!P9:T9) -> 10945.825 | G10: =SUM('Motor Semanal'!U9:Y9) -> 12393.374 | H10: =SUM('Motor Semanal'!Z9:AD9) -> 9631.5746 | I10: =SUM('Motor Semanal'!AE9:AI9) -> 12526.86 | J10: =SUM('Motor Semanal'!AJ9:AN9) -> 13904.901 | K10: =SUM('Motor Semanal'!AO9:AS9) -> 13278.453 | L10: =SUM('Motor Semanal'!AT9:AX9) -> 13619.536 | M10: =SUM('Motor Semanal'!AY9:BC9) -> 12809.204 | N10: =SUM('Motor Semanal'!BD9:BH9) -> 6641.4291 | O10: =SUM('Motor Semanal'!BI9:BM9) -> 15141.714 | P10: =SUM('Motor Semanal'!BN9:BQ9) -> 12756.537 | Q10: =SUM('Motor Semanal'!BR9:BV9) -> 13747.522 | R10: =SUM('Motor Semanal'!BW9:CA9) -> 13299.178 | S10: =SUM('Motor Semanal'!CB9:CF9) -> 15057.95 | T10: =SUM('Motor Semanal'!CG9:CK9) -> 11702.363 | U10: =SUM('Motor Semanal'!CL9:CP9) -> 15330.538 | V10: =SUM('Motor Semanal'!CQ9:CU9) -> 16894.455 | W10: =SUM('Motor Semanal'!CV9:CZ9) -> 16133.321 | X10: =SUM('Motor Semanal'!DA9:DE9) -> 16547.737 | Y10: =SUM('Motor Semanal'!DF9:DJ9) -> 15563.183 | Z10: =SUM('Motor Semanal'!DK9:DO9) -> 8069.3363 | AA10: =SUM('Motor Semanal'!DP9:DT9) -> 17715.805 | AB10: =SUM('Motor Semanal'!DU9:DY9) -> 14925.148 | AC10: =SUM('Motor Semanal'!DZ9:ED9) -> 16084.6 | AD10: =SUM('Motor Semanal'!EE9:EI9) -> 15560.038 | AE10: =SUM('Motor Semanal'!EJ9:EN9) -> 17617.801 | AF10: =SUM('Motor Semanal'!EO9:ES9) -> 13691.765 | AG10: =SUM('Motor Semanal'!ET9:EX9) -> 17807.557 | AH10: =SUM('Motor Semanal'!EY9:FC9) -> 19766.512 | AI10: =SUM('Motor Semanal'!FD9:FH9) -> 18875.985 | AJ10: =SUM('Motor Semanal'!FI9:FM9) -> 19360.852 | AK10: =SUM('Motor Semanal'!FN9:FR9) -> 18208.924 | AL10: =SUM('Motor Semanal'!FS9:FW9) -> 9441.1235 | AM10: =SUM('Motor Semanal'!FX9:GB9) -> 20638.913 | AN10: =SUM('Motor Semanal'!GC9:GF9) -> 17387.797 | AO10: =SUM('Motor Semanal'!GG9:GK9) -> 18738.559 | AP10: =SUM('Motor Semanal'!GL9:GP9) -> 18127.444 | AQ10: =SUM('Motor Semanal'!GQ9:GU9) -> 20524.738 | AR10: =SUM('Motor Semanal'!GV9:GZ9) -> 15950.906 | AS10: =SUM('Motor Semanal'!HA9:HE9) -> 20745.804 | AT10: =SUM('Motor Semanal'!HF9:HJ9) -> 23027.986 | AU10: =SUM('Motor Semanal'!HK9:HO9) -> 21990.523 | AV10: =SUM('Motor Semanal'!HP9:HT9) -> 22555.392 | AW10: =SUM('Motor Semanal'!HU9:HY9) -> 21213.396 | AX10: =SUM('Motor Semanal'!HZ9:ID9) -> 10998.909 | AY10: =SUM('Motor Semanal'!IE9:II9) -> 23941.139 | AZ10: =SUM('Motor Semanal'!IJ9:IM9) -> 20169.845 | BA10: =SUM('Motor Semanal'!IN9:IR9) -> 21736.729 | BB10: =SUM('Motor Semanal'!IS9:IW9) -> 21027.835 | BC10: =SUM('Motor Semanal'!IX9:JB9) -> 23808.696 | BD10: =SUM('Motor Semanal'!JC9:JG9) -> 18503.051 | BE10: =SUM('Motor Semanal'!JH9:JL9) -> 24065.133 | BF10: =SUM('Motor Semanal'!JM9:JQ9) -> 26712.464 | BG10: =SUM('Motor Semanal'!JR9:JV9) -> 25509.007 | BH10: =SUM('Motor Semanal'!JW9:KA9) -> 26164.255 | BI10: =SUM('Motor Semanal'!KB9:KF9) -> 24607.54 | BJ10: =SUM('Motor Semanal'!KG9:KK9) -> 12758.734 | BK10: =SUM('Motor Semanal'!KL9:KP9) -> 27652.016 | BL10: =SUM('Motor Semanal'!KQ9:KT9) -> 23296.171 | BM10: =SUM('Motor Semanal'!KU9:KY9) -> 25105.922 | BN10: =SUM('Motor Semanal'!KZ9:LD9) -> 24287.149 | BO10: =SUM('Motor Semanal'!LE9:LI9) -> 27499.044 | BP10: =SUM('Motor Semanal'!LJ9:LN9) -> 21371.024 | BQ10: =SUM('Motor Semanal'!LO9:LS9) -> 27795.229 | BR10: =SUM('Motor Semanal'!LT9:LX9) -> 30852.896 | BS10: =SUM('Motor Semanal'!LY9:MC9) -> 29462.903 | BT10: =SUM('Motor Semanal'!MD9:MH9) -> 30219.715 | BU10: =SUM('Motor Semanal'!MI9:MM9) -> 28421.708 | BV10: =SUM('Motor Semanal'!MN9:MR9) -> 14736.338 | BW10: =SUM('Motor Semanal'!MS9:MW9) -> 31523.298 | BX10: =SUM('Motor Semanal'!MX9:NB9) -> 26557.634 | BY10: =SUM('Motor Semanal'!NC9:NG9) -> 28620.751 | BZ10: =SUM('Motor Semanal'!NH9:NL9) -> 27687.35 | CA10: =SUM('Motor Semanal'!NM9:NQ9) -> 31348.91 | CB10: =SUM('Motor Semanal'!NR9:NV9) -> 24362.967 | CC10: =SUM('Motor Semanal'!NW9:OA9) -> 31686.561 | CD10: =SUM('Motor Semanal'!OB9:OF9) -> 35172.301 | CE10: =SUM('Motor Semanal'!OG9:OK9) -> 33587.709 | CF10: =SUM('Motor Semanal'!OL9:OP9) -> 34450.475 | CG10: =SUM('Motor Semanal'!OQ9:OU9) -> 32400.748 | CH10: =SUM('Motor Semanal'!OV9:OZ9) -> 16799.425 | CI10: =SUM('Motor Semanal'!PA9:PE9) -> 35936.56 | CJ10: =SUM('Motor Semanal'!PF9:PI9) -> 30275.703 | CK10: =SUM('Motor Semanal'!PJ9:PN9) -> 32627.656 | CL10: =SUM('Motor Semanal'!PO9:PS9) -> 31563.579 | CM10: =SUM('Motor Semanal'!PT9:PX9) -> 35737.758 | CN10: =SUM('Motor Semanal'!PY9:QC9) -> 27773.783 | CO10: =SUM('Motor Semanal'!QD9:QH9) -> 36122.679 | CP10: =SUM('Motor Semanal'!QI9:QM9) -> 40096.424 | CQ10: =SUM('Motor Semanal'!QN9:QR9) -> 38289.988 | CR10: =SUM('Motor Semanal'!QS9:QW9) -> 39273.541 | CS10: =SUM('Motor Semanal'!QX9:RB9) -> 36936.852 | CT10: =SUM('Motor Semanal'!RC9:RG9) -> 19151.345 | CU10: =SUM('Motor Semanal'!RH9:RL9) -> 40967.679 | CV10: =SUM('Motor Semanal'!RM9:RP9) -> 34514.302 | CW10: =SUM('Motor Semanal'!RQ9:RU9) -> 37195.528 | CX10: =SUM('Motor Semanal'!RV9:RZ9) -> 35982.481 | CY10: =SUM('Motor Semanal'!SA9:SE9) -> 40741.044 | CZ10: =SUM('Motor Semanal'!SF9:SJ9) -> 31662.112 | DA10: =SUM('Motor Semanal'!SK9:SO9) -> 41179.854 | DB10: =SUM('Motor Semanal'!SP9:ST9) -> 45709.923 | DC10: =SUM('Motor Semanal'!SU9:SY9) -> 43650.587 | DD10: =SUM('Motor Semanal'!SZ9:TD9) -> 44771.837 | DE10: =SUM('Motor Semanal'!TE9:TI9) -> 42108.012 | DF10: =SUM('Motor Semanal'!TJ9:TN9) -> 21832.533 | DG10: =CU10*(1+Supuestos!$B$21) -> 46703.154 | DH10: =CV10*(1+Supuestos!$B$21) -> 39346.304
A11: Cobro de ventas al contado | B11: Motor Semanal fila 11 | C11: =SUM('Motor Semanal'!B11:F11) -> 7688.3132 | D11: =SUM('Motor Semanal'!G11:J11) -> 5675.1535 | E11: =SUM('Motor Semanal'!K11:O11) -> 7124.4154 | F11: =SUM('Motor Semanal'!P11:T11) -> 6782.2126 | G11: =SUM('Motor Semanal'!U11:Y11) -> 7152.0433 | H11: =SUM('Motor Semanal'!Z11:AD11) -> 5920.7573 | I11: =SUM('Motor Semanal'!AE11:AI11) -> 6807.6876 | J11: =SUM('Motor Semanal'!AJ11:AN11) -> 10057.844 | K11: =SUM('Motor Semanal'!AO11:AS11) -> 8539.6445 | L11: =SUM('Motor Semanal'!AT11:AX11) -> 9022.8435 | M11: =SUM('Motor Semanal'!AY11:BC11) -> 8485.1913 | N11: =SUM('Motor Semanal'!BD11:BH11) -> 4620.1851 | O11: =SUM('Motor Semanal'!BI11:BM11) -> 9667.1212 | P11: =SUM('Motor Semanal'!BN11:BQ11) -> 7833.6257 | Q11: =SUM('Motor Semanal'!BR11:BV11) -> 9712.5895 | R11: =SUM('Motor Semanal'!BW11:CA11) -> 8794.6736 | S11: =SUM('Motor Semanal'!CB11:CF11) -> 9870.71 | T11: =SUM('Motor Semanal'!CG11:CK11) -> 7852.4139 | U11: =SUM('Motor Semanal'!CL11:CP11) -> 9910.2067 | V11: =SUM('Motor Semanal'!CQ11:CU11) -> 11086.046 | W11: =SUM('Motor Semanal'!CV11:CZ11) -> 10677.219 | X11: =SUM('Motor Semanal'!DA11:DE11) -> 10905.593 | Y11: =SUM('Motor Semanal'!DF11:DJ11) -> 10309.507 | Z11: =SUM('Motor Semanal'!DK11:DO11) -> 5613.5249 | AA11: =SUM('Motor Semanal'!DP11:DT11) -> 11322.008 | AB11: =SUM('Motor Semanal'!DU11:DY11) -> 9957.7585 | AC11: =SUM('Motor Semanal'!DZ11:ED11) -> 10571.313 | AD11: =SUM('Motor Semanal'!EE11:EI11) -> 10289.768 | AE11: =SUM('Motor Semanal'!EJ11:EN11) -> 11548.731 | AF11: =SUM('Motor Semanal'!EO11:ES11) -> 9187.3242 | AG11: =SUM('Motor Semanal'!ET11:EX11) -> 11594.942 | AH11: =SUM('Motor Semanal'!EY11:FC11) -> 12970.674 | AI11: =SUM('Motor Semanal'!FD11:FH11) -> 12492.347 | AJ11: =SUM('Motor Semanal'!FI11:FM11) -> 12759.543 | AK11: =SUM('Motor Semanal'!FN11:FR11) -> 12062.124 | AL11: =SUM('Motor Semanal'!FS11:FW11) -> 6567.8241 | AM11: =SUM('Motor Semanal'!FX11:GB11) -> 13191.689 | AN11: =SUM('Motor Semanal'!GC11:GF11) -> 10677.624 | AO11: =SUM('Motor Semanal'!GG11:GK11) -> 13238.745 | AP11: =SUM('Motor Semanal'!GL11:GP11) -> 11987.58 | AQ11: =SUM('Motor Semanal'!GQ11:GU11) -> 13454.271 | AR11: =SUM('Motor Semanal'!GV11:GZ11) -> 10703.233 | AS11: =SUM('Motor Semanal'!HA11:HE11) -> 13508.107 | AT11: =SUM('Motor Semanal'!HF11:HJ11) -> 15110.835 | AU11: =SUM('Motor Semanal'!HK11:HO11) -> 14553.584 | AV11: =SUM('Motor Semanal'!HP11:HT11) -> 14864.868 | AW11: =SUM('Motor Semanal'!HU11:HY11) -> 14052.374 | AX11: =SUM('Motor Semanal'!HZ11:ID11) -> 7651.5151 | AY11: =SUM('Motor Semanal'!IE11:II11) -> 15304.172 | AZ11: =SUM('Motor Semanal'!IJ11:IM11) -> 12386.043 | BA11: =SUM('Motor Semanal'!IN11:IR11) -> 15356.944 | BB11: =SUM('Motor Semanal'!IS11:IW11) -> 13905.593 | BC11: =SUM('Motor Semanal'!IX11:JB11) -> 15606.955 | BD11: =SUM('Motor Semanal'!JC11:JG11) -> 12415.75 | BE11: =SUM('Motor Semanal'!JH11:JL11) -> 15669.404 | BF11: =SUM('Motor Semanal'!JM11:JQ11) -> 17528.569 | BG11: =SUM('Motor Semanal'!JR11:JV11) -> 16882.157 | BH11: =SUM('Motor Semanal'!JW11:KA11) -> 17243.247 | BI11: =SUM('Motor Semanal'!KB11:KF11) -> 16300.754 | BJ11: =SUM('Motor Semanal'!KG11:KK11) -> 8875.7575 | BK11: =SUM('Motor Semanal'!KL11:KP11) -> 17678.43 | BL11: =SUM('Motor Semanal'!KQ11:KT11) -> 14305.88 | BM11: =SUM('Motor Semanal'!KU11:KY11) -> 17737.271 | BN11: =SUM('Motor Semanal'!KZ11:LD11) -> 16060.959 | BO11: =SUM('Motor Semanal'!LE11:LI11) -> 18026.033 | BP11: =SUM('Motor Semanal'!LJ11:LN11) -> 14340.191 | BQ11: =SUM('Motor Semanal'!LO11:LS11) -> 18098.162 | BR11: =SUM('Motor Semanal'!LT11:LX11) -> 20245.497 | BS11: =SUM('Motor Semanal'!LY11:MC11) -> 19498.891 | BT11: =SUM('Motor Semanal'!MD11:MH11) -> 19915.95 | BU11: =SUM('Motor Semanal'!MI11:MM11) -> 18827.371 | BV11: =SUM('Motor Semanal'!MN11:MR11) -> 10251.5 | BW11: =SUM('Motor Semanal'!MS11:MW11) -> 20160.759 | BX11: =SUM('Motor Semanal'!MX11:NB11) -> 17718.72 | BY11: =SUM('Motor Semanal'!NC11:NG11) -> 18810.472 | BZ11: =SUM('Motor Semanal'!NH11:NL11) -> 18309.494 | CA11: =SUM('Motor Semanal'!NM11:NQ11) -> 20549.677 | CB11: =SUM('Motor Semanal'!NR11:NV11) -> 16347.818 | CC11: =SUM('Motor Semanal'!NW11:OA11) -> 20631.905 | CD11: =SUM('Motor Semanal'!OB11:OF11) -> 23079.867 | CE11: =SUM('Motor Semanal'!OG11:OK11) -> 22228.736 | CF11: =SUM('Motor Semanal'!OL11:OP11) -> 22704.183 | CG11: =SUM('Motor Semanal'!OQ11:OU11) -> 21463.203 | CH11: =SUM('Motor Semanal'!OV11:OZ11) -> 11686.71 | CI11: =SUM('Motor Semanal'!PA11:PE11) -> 22983.266 | CJ11: =SUM('Motor Semanal'!PF11:PI11) -> 18591.922 | CK11: =SUM('Motor Semanal'!PJ11:PN11) -> 23051.357 | CL11: =SUM('Motor Semanal'!PO11:PS11) -> 20872.823 | CM11: =SUM('Motor Semanal'!PT11:PX11) -> 23426.632 | CN11: =SUM('Motor Semanal'!PY11:QC11) -> 18636.513 | CO11: =SUM('Motor Semanal'!QD11:QH11) -> 23520.371 | CP11: =SUM('Motor Semanal'!QI11:QM11) -> 26311.048 | CQ11: =SUM('Motor Semanal'!QN11:QR11) -> 25340.759 | CR11: =SUM('Motor Semanal'!QS11:QW11) -> 25882.769 | CS11: =SUM('Motor Semanal'!QX11:RB11) -> 24468.051 | CT11: =SUM('Motor Semanal'!RC11:RG11) -> 13322.849 | CU11: =SUM('Motor Semanal'!RH11:RL11) -> 26200.923 | CV11: =SUM('Motor Semanal'!RM11:RP11) -> 21194.791 | CW11: =SUM('Motor Semanal'!RQ11:RU11) -> 26278.547 | CX11: =SUM('Motor Semanal'!RV11:RZ11) -> 23795.018 | CY11: =SUM('Motor Semanal'!SA11:SE11) -> 26706.361 | CZ11: =SUM('Motor Semanal'!SF11:SJ11) -> 21245.624 | DA11: =SUM('Motor Semanal'!SK11:SO11) -> 26813.223 | DB11: =SUM('Motor Semanal'!SP11:ST11) -> 29994.595 | DC11: =SUM('Motor Semanal'!SU11:SY11) -> 28888.466 | DD11: =SUM('Motor Semanal'!SZ11:TD11) -> 29506.357 | DE11: =SUM('Motor Semanal'!TE11:TI11) -> 27893.578 | DF11: =SUM('Motor Semanal'!TJ11:TN11) -> 15188.048
A12: Cobro por descuento de letras | B12: Motor Semanal fila 13 | C12: =SUM('Motor Semanal'!B13:F13) -> 1568.047 | D12: =SUM('Motor Semanal'!G13:J13) -> 1460.4981 | E12: =SUM('Motor Semanal'!K13:O13) -> 2685.4251 | F12: =SUM('Motor Semanal'!P13:T13) -> 1803.1158 | G12: =SUM('Motor Semanal'!U13:Y13) -> 2486.2205 | H12: =SUM('Motor Semanal'!Z13:AD13) -> 1743.6983 | I12: =SUM('Motor Semanal'!AE13:AI13) -> 2482.6376 | J12: =SUM('Motor Semanal'!AJ13:AN13) -> 2223.8702 | K12: =SUM('Motor Semanal'!AO13:AS13) -> 1806.6361 | L12: =SUM('Motor Semanal'!AT13:AX13) -> 2156.9122 | M12: =SUM('Motor Semanal'!AY13:BC13) -> 2027.9385 | N12: =SUM('Motor Semanal'!BD13:BH13) -> 1225.8007 | O12: =SUM('Motor Semanal'!BI13:BM13) -> 2110.3331 | P12: =SUM('Motor Semanal'!BN13:BQ13) -> 1532.4876 | Q12: =SUM('Motor Semanal'!BR13:BV13) -> 2655.0358 | R12: =SUM('Motor Semanal'!BW13:CA13) -> 2093.5906 | S12: =SUM('Motor Semanal'!CB13:CF13) -> 2301.7162 | T12: =SUM('Motor Semanal'!CG13:CK13) -> 1932.0314 | U12: =SUM('Motor Semanal'!CL13:CP13) -> 2273.7279 | V12: =SUM('Motor Semanal'!CQ13:CU13) -> 2642.2927 | W12: =SUM('Motor Semanal'!CV13:CZ13) -> 2546.3381 | X12: =SUM('Motor Semanal'!DA13:DE13) -> 2575.4959 | Y12: =SUM('Motor Semanal'!DF13:DJ13) -> 2463.9453 | Z12: =SUM('Motor Semanal'!DK13:DO13) -> 1489.3478 | AA12: =SUM('Motor Semanal'!DP13:DT13) -> 2478.1549 | AB12: =SUM('Motor Semanal'!DU13:DY13) -> 2418.9394 | AC12: =SUM('Motor Semanal'!DZ13:ED13) -> 2480.4629 | AD12: =SUM('Motor Semanal'!EE13:EI13) -> 2449.501 | AE12: =SUM('Motor Semanal'!EJ13:EN13) -> 2693.0079 | AF12: =SUM('Motor Semanal'!EO13:ES13) -> 2260.4767 | AG12: =SUM('Motor Semanal'!ET13:EX13) -> 2660.2616 | AH12: =SUM('Motor Semanal'!EY13:FC13) -> 3032.0634 | AI12: =SUM('Motor Semanal'!FD13:FH13) -> 2979.2156 | AJ12: =SUM('Motor Semanal'!FI13:FM13) -> 3013.3302 | AK12: =SUM('Motor Semanal'!FN13:FR13) -> 2882.816 | AL12: =SUM('Motor Semanal'!FS13:FW13) -> 1742.537 | AM12: =SUM('Motor Semanal'!FX13:GB13) -> 2888.2743 | AN12: =SUM('Motor Semanal'!GC13:GF13) -> 2088.8573 | AO12: =SUM('Motor Semanal'!GG13:GK13) -> 3618.9465 | AP12: =SUM('Motor Semanal'!GL13:GP13) -> 2853.6686 | AQ12: =SUM('Motor Semanal'!GQ13:GU13) -> 3137.3542 | AR12: =SUM('Motor Semanal'!GV13:GZ13) -> 2633.4554 | AS12: =SUM('Motor Semanal'!HA13:HE13) -> 3099.2048 | AT12: =SUM('Motor Semanal'!HF13:HJ13) -> 3532.3538 | AU12: =SUM('Motor Semanal'!HK13:HO13) -> 3470.7862 | AV12: =SUM('Motor Semanal'!HP13:HT13) -> 3510.5297 | AW12: =SUM('Motor Semanal'!HU13:HY13) -> 3358.4807 | AX12: =SUM('Motor Semanal'!HZ13:ID13) -> 2030.0556 | AY12: =SUM('Motor Semanal'!IE13:II13) -> 3351.83 | AZ12: =SUM('Motor Semanal'!IJ13:IM13) -> 2423.0744 | BA12: =SUM('Motor Semanal'!IN13:IR13) -> 4197.9779 | BB12: =SUM('Motor Semanal'!IS13:IW13) -> 3310.2556 | BC12: =SUM('Motor Semanal'!IX13:JB13) -> 3639.3309 | BD12: =SUM('Motor Semanal'!JC13:JG13) -> 3054.8082 | BE12: =SUM('Motor Semanal'!JH13:JL13) -> 3595.0775 | BF12: =SUM('Motor Semanal'!JM13:JQ13) -> 4097.5304 | BG12: =SUM('Motor Semanal'!JR13:JV13) -> 4026.112 | BH12: =SUM('Motor Semanal'!JW13:KA13) -> 4072.2145 | BI12: =SUM('Motor Semanal'!KB13:KF13) -> 3895.8376 | BJ12: =SUM('Motor Semanal'!KG13:KK13) -> 2354.8645 | BK12: =SUM('Motor Semanal'!KL13:KP13) -> 3873.0317 | BL12: =SUM('Motor Semanal'!KQ13:KT13) -> 2798.651 | BM12: =SUM('Motor Semanal'!KU13:KY13) -> 4848.6645 | BN12: =SUM('Motor Semanal'!KZ13:LD13) -> 3823.3452 | BO12: =SUM('Motor Semanal'!LE13:LI13) -> 4203.4272 | BP12: =SUM('Motor Semanal'!LJ13:LN13) -> 3528.3035 | BQ12: =SUM('Motor Semanal'!LO13:LS13) -> 4152.3145 | BR12: =SUM('Motor Semanal'!LT13:LX13) -> 4732.6477 | BS12: =SUM('Motor Semanal'!LY13:MC13) -> 4650.1593 | BT12: =SUM('Motor Semanal'!MD13:MH13) -> 4703.4077 | BU12: =SUM('Motor Semanal'!MI13:MM13) -> 4499.6924 | BV12: =SUM('Motor Semanal'!MN13:MR13) -> 2719.8685 | BW12: =SUM('Motor Semanal'!MS13:MW13) -> 4421.0611 | BX12: =SUM('Motor Semanal'!MX13:NB13) -> 4304.2327 | BY12: =SUM('Motor Semanal'!NC13:NG13) -> 4413.7069 | BZ12: =SUM('Motor Semanal'!NH13:NL13) -> 4358.6135 | CA12: =SUM('Motor Semanal'!NM13:NQ13) -> 4791.907 | CB12: =SUM('Motor Semanal'!NR13:NV13) -> 4022.266 | CC12: =SUM('Motor Semanal'!NW13:OA13) -> 4733.6386 | CD12: =SUM('Motor Semanal'!OB13:OF13) -> 5395.2183 | CE12: =SUM('Motor Semanal'!OG13:OK13) -> 5301.1816 | CF12: =SUM('Motor Semanal'!OL13:OP13) -> 5361.8848 | CG12: =SUM('Motor Semanal'!OQ13:OU13) -> 5129.6493 | CH12: =SUM('Motor Semanal'!OV13:OZ13) -> 3100.65 | CI12: =SUM('Motor Semanal'!PA13:PE13) -> 5040.0097 | CJ12: =SUM('Motor Semanal'!PF13:PI13) -> 3637.1268 | CK12: =SUM('Motor Semanal'!PJ13:PN13) -> 6301.3244 | CL12: =SUM('Motor Semanal'!PO13:PS13) -> 4968.8194 | CM12: =SUM('Motor Semanal'!PT13:PX13) -> 5462.774 | CN12: =SUM('Motor Semanal'!PY13:QC13) -> 4585.3832 | CO12: =SUM('Motor Semanal'!QD13:QH13) -> 5396.348 | CP12: =SUM('Motor Semanal'!QI13:QM13) -> 6150.5489 | CQ12: =SUM('Motor Semanal'!QN13:QR13) -> 6043.3471 | CR12: =SUM('Motor Semanal'!QS13:QW13) -> 6112.5487 | CS12: =SUM('Motor Semanal'!QX13:RB13) -> 5847.8002 | CT12: =SUM('Motor Semanal'!RC13:RG13) -> 3534.741 | CU12: =SUM('Motor Semanal'!RH13:RL13) -> 5745.6111 | CV12: =SUM('Motor Semanal'!RM13:RP13) -> 4146.3245 | CW12: =SUM('Motor Semanal'!RQ13:RU13) -> 7183.5098 | CX12: =SUM('Motor Semanal'!RV13:RZ13) -> 5664.4541 | CY12: =SUM('Motor Semanal'!SA13:SE13) -> 6227.5623 | CZ12: =SUM('Motor Semanal'!SF13:SJ13) -> 5227.3369 | DA12: =SUM('Motor Semanal'!SK13:SO13) -> 6151.8367 | DB12: =SUM('Motor Semanal'!SP13:ST13) -> 7011.6257 | DC12: =SUM('Motor Semanal'!SU13:SY13) -> 6889.4156 | DD12: =SUM('Motor Semanal'!SZ13:TD13) -> 6968.3055 | DE12: =SUM('Motor Semanal'!TE13:TI13) -> 6666.4923 | DF12: =SUM('Motor Semanal'!TJ13:TN13) -> 4029.6048
A13: Cobranza libre / cartera | B13: Motor Semanal fila 14 | C13: =SUM('Motor Semanal'!B14:F14) -> 29.442892 | D13: =SUM('Motor Semanal'!G14:J14) -> 1064.6493 | E13: =SUM('Motor Semanal'!K14:O14) -> 2473.9772 | F13: =SUM('Motor Semanal'!P14:T14) -> 2865.4535 | G13: =SUM('Motor Semanal'!U14:Y14) -> 2238.0926 | H13: =SUM('Motor Semanal'!Z14:AD14) -> 2740.2836 | I13: =SUM('Motor Semanal'!AE14:AI14) -> 2244.1559 | J13: =SUM('Motor Semanal'!AJ14:AN14) -> 2704.9998 | K13: =SUM('Motor Semanal'!AO14:AS14) -> 2734.799 | L13: =SUM('Motor Semanal'!AT14:AX14) -> 2089.7689 | M13: =SUM('Motor Semanal'!AY14:BC14) -> 2543.5802 | N13: =SUM('Motor Semanal'!BD14:BH14) -> 2376.1561 | O13: =SUM('Motor Semanal'!BI14:BM14) -> 1596.4435 | P13: =SUM('Motor Semanal'!BN14:BQ14) -> 1717.9558 | Q13: =SUM('Motor Semanal'!BR14:BV14) -> 2614.0617 | R13: =SUM('Motor Semanal'!BW14:CA14) -> 2907.1593 | S13: =SUM('Motor Semanal'!CB14:CF14) -> 2473.0789 | T13: =SUM('Motor Semanal'!CG14:CK14) -> 2653.8968 | U13: =SUM('Motor Semanal'!CL14:CP14) -> 2349.8812 | V13: =SUM('Motor Semanal'!CQ14:CU14) -> 2613.7985 | W13: =SUM('Motor Semanal'!CV14:CZ14) -> 3052.4937 | X13: =SUM('Motor Semanal'!DA14:DE14) -> 3006.4196 | Y13: =SUM('Motor Semanal'!DF14:DJ14) -> 3011.4009 | Z13: =SUM('Motor Semanal'!DK14:DO14) -> 2887.0297 | AA13: =SUM('Motor Semanal'!DP14:DT14) -> 1937.3259 | AB13: =SUM('Motor Semanal'!DU14:DY14) -> 2699.1406 | AC13: =SUM('Motor Semanal'!DZ14:ED14) -> 2901.5914 | AD13: =SUM('Motor Semanal'!EE14:EI14) -> 2885.9541 | AE13: =SUM('Motor Semanal'!EJ14:EN14) -> 2893.5023 | AF13: =SUM('Motor Semanal'!EO14:ES14) -> 3105.0593 | AG13: =SUM('Motor Semanal'!ET14:EX14) -> 2749.361 | AH13: =SUM('Motor Semanal'!EY14:FC14) -> 3044.1937 | AI13: =SUM('Motor Semanal'!FD14:FH14) -> 3515.6153 | AJ13: =SUM('Motor Semanal'!FI14:FM14) -> 3517.511 | AK13: =SUM('Motor Semanal'!FN14:FR14) -> 3523.339 | AL13: =SUM('Motor Semanal'!FS14:FW14) -> 3377.8248 | AM13: =SUM('Motor Semanal'!FX14:GB14) -> 2266.3654 | AN13: =SUM('Motor Semanal'!GC14:GF14) -> 2363.5637 | AO13: =SUM('Motor Semanal'!GG14:GK14) -> 3563.0968 | AP13: =SUM('Motor Semanal'!GL14:GP14) -> 3962.6035 | AQ13: =SUM('Motor Semanal'!GQ14:GU14) -> 3370.9302 | AR13: =SUM('Motor Semanal'!GV14:GZ14) -> 3617.3941 | AS13: =SUM('Motor Semanal'!HA14:HE14) -> 3203.0055 | AT13: =SUM('Motor Semanal'!HF14:HJ14) -> 3546.4856 | AU13: =SUM('Motor Semanal'!HK14:HO14) -> 4095.6918 | AV13: =SUM('Motor Semanal'!HP14:HT14) -> 4097.9003 | AW13: =SUM('Motor Semanal'!HU14:HY14) -> 4104.6899 | AX13: =SUM('Motor Semanal'!HZ14:ID14) -> 3935.1658 | AY13: =SUM('Motor Semanal'!IE14:II14) -> 2639.9594 | AZ13: =SUM('Motor Semanal'!IJ14:IM14) -> 2744.3952 | BA13: =SUM('Motor Semanal'!IN14:IR14) -> 4133.1923 | BB13: =SUM('Motor Semanal'!IS14:IW14) -> 4596.62 | BC13: =SUM('Motor Semanal'!IX14:JB14) -> 3910.279 | BD13: =SUM('Motor Semanal'!JC14:JG14) -> 4196.1772 | BE13: =SUM('Motor Semanal'!JH14:JL14) -> 3715.4864 | BF13: =SUM('Motor Semanal'!JM14:JQ14) -> 4113.9233 | BG13: =SUM('Motor Semanal'!JR14:JV14) -> 4751.0025 | BH13: =SUM('Motor Semanal'!JW14:KA14) -> 4753.5643 | BI13: =SUM('Motor Semanal'!KB14:KF14) -> 4761.4403 | BJ13: =SUM('Motor Semanal'!KG14:KK14) -> 4564.7924 | BK13: =SUM('Motor Semanal'!KL14:KP14) -> 3061.9395 | BL13: =SUM('Motor Semanal'!KQ14:KT14) -> 3172.877 | BM13: =SUM('Motor Semanal'!KU14:KY14) -> 4773.8371 | BN13: =SUM('Motor Semanal'!KZ14:LD14) -> 5309.0961 | BO13: =SUM('Motor Semanal'!LE14:LI14) -> 4516.3722 | BP13: =SUM('Motor Semanal'!LJ14:LN14) -> 4846.5846 | BQ13: =SUM('Motor Semanal'!LO14:LS14) -> 4291.3868 | BR13: =SUM('Motor Semanal'!LT14:LX14) -> 4751.5814 | BS13: =SUM('Motor Semanal'!LY14:MC14) -> 5487.4079 | BT13: =SUM('Motor Semanal'!MD14:MH14) -> 5490.3668 | BU13: =SUM('Motor Semanal'!MI14:MM14) -> 5499.4636 | BV13: =SUM('Motor Semanal'!MN14:MR14) -> 5272.3352 | BW13: =SUM('Motor Semanal'!MS14:MW14) -> 3535.1079 | BX13: =SUM('Motor Semanal'!MX14:NB14) -> 4824.122 | BY13: =SUM('Motor Semanal'!NC14:NG14) -> 5163.0581 | BZ13: =SUM('Motor Semanal'!NH14:NL14) -> 5135.2331 | CA13: =SUM('Motor Semanal'!NM14:NQ14) -> 5148.6643 | CB13: =SUM('Motor Semanal'!NR14:NV14) -> 5525.1065 | CC13: =SUM('Motor Semanal'!NW14:OA14) -> 4892.181 | CD13: =SUM('Motor Semanal'!OB14:OF14) -> 5416.8028 | CE13: =SUM('Motor Semanal'!OG14:OK14) -> 6255.645 | CF13: =SUM('Motor Semanal'!OL14:OP14) -> 6259.0182 | CG13: =SUM('Motor Semanal'!OQ14:OU14) -> 6269.3885 | CH13: =SUM('Motor Semanal'!OV14:OZ14) -> 6010.4621 | CI13: =SUM('Motor Semanal'!PA14:PE14) -> 4030.023 | CJ13: =SUM('Motor Semanal'!PF14:PI14) -> 4135.771 | CK13: =SUM('Motor Semanal'!PJ14:PN14) -> 6204.0788 | CL13: =SUM('Motor Semanal'!PO14:PS14) -> 6899.7013 | CM13: =SUM('Motor Semanal'!PT14:PX14) -> 5869.4773 | CN13: =SUM('Motor Semanal'!PY14:QC14) -> 6298.6214 | CO13: =SUM('Motor Semanal'!QD14:QH14) -> 5577.0863 | CP13: =SUM('Motor Semanal'!QI14:QM14) -> 6175.1552 | CQ13: =SUM('Motor Semanal'!QN14:QR14) -> 7131.4353 | CR13: =SUM('Motor Semanal'!QS14:QW14) -> 7135.2807 | CS13: =SUM('Motor Semanal'!QX14:RB14) -> 7147.1029 | CT13: =SUM('Motor Semanal'!RC14:RG14) -> 6851.9268 | CU13: =SUM('Motor Semanal'!RH14:RL14) -> 4594.2262 | CV13: =SUM('Motor Semanal'!RM14:RP14) -> 4714.779 | CW13: =SUM('Motor Semanal'!RQ14:RU14) -> 7072.6498 | CX13: =SUM('Motor Semanal'!RV14:RZ14) -> 7865.6595 | CY13: =SUM('Motor Semanal'!SA14:SE14) -> 6691.2042 | CZ13: =SUM('Motor Semanal'!SF14:SJ14) -> 7180.4284 | DA13: =SUM('Motor Semanal'!SK14:SO14) -> 6357.8784 | DB13: =SUM('Motor Semanal'!SP14:ST14) -> 7039.6769 | DC13: =SUM('Motor Semanal'!SU14:SY14) -> 8129.8363 | DD13: =SUM('Motor Semanal'!SZ14:TD14) -> 8134.22 | DE13: =SUM('Motor Semanal'!TE14:TI14) -> 8147.6973 | DF13: =SUM('Motor Semanal'!TJ14:TN14) -> 7811.1966
A14: (−) Incobrables | B14: Motor Semanal fila 16 (% fila 59) | C14: =-SUM('Motor Semanal'!B16:F16) -> -162.01011 | D14: =-SUM('Motor Semanal'!G16:J16) -> -136.48969 | E14: =-SUM('Motor Semanal'!K16:O16) -> -147.09282 | F14: =-SUM('Motor Semanal'!P16:T16) -> -142.29573 | G14: =-SUM('Motor Semanal'!U16:Y16) -> -161.11386 | H14: =-SUM('Motor Semanal'!Z16:AD16) -> -125.21047 | I14: =-SUM('Motor Semanal'!AE16:AI16) -> -162.84918 | J14: =-SUM('Motor Semanal'!AJ16:AN16) -> -180.76371 | K14: =-SUM('Motor Semanal'!AO16:AS16) -> -172.61989 | L14: =-SUM('Motor Semanal'!AT16:AX16) -> -177.05397 | M14: =-SUM('Motor Semanal'!AY16:BC16) -> -166.51965 | N14: =-SUM('Motor Semanal'!BD16:BH16) -> -86.338578 | O14: =-SUM('Motor Semanal'!BI16:BM16) -> -181.70057 | P14: =-SUM('Motor Semanal'!BN16:BQ16) -> -153.07844 | Q14: =-SUM('Motor Semanal'!BR16:BV16) -> -164.97026 | R14: =-SUM('Motor Semanal'!BW16:CA16) -> -159.59013 | S14: =-SUM('Motor Semanal'!CB16:CF16) -> -180.69539 | T14: =-SUM('Motor Semanal'!CG16:CK16) -> -140.42836 | U14: =-SUM('Motor Semanal'!CL16:CP16) -> -183.96645 | V14: =-SUM('Motor Semanal'!CQ16:CU16) -> -202.73345 | W14: =-SUM('Motor Semanal'!CV16:CZ16) -> -193.59985 | X14: =-SUM('Motor Semanal'!DA16:DE16) -> -198.57284 | Y14: =-SUM('Motor Semanal'!DF16:DJ16) -> -186.75819 | Z14: =-SUM('Motor Semanal'!DK16:DO16) -> -96.832036 | AA14: =-SUM('Motor Semanal'!DP16:DT16) -> -194.87386 | AB14: =-SUM('Motor Semanal'!DU16:DY16) -> -164.17663 | AC14: =-SUM('Motor Semanal'!DZ16:ED16) -> -176.9306 | AD14: =-SUM('Motor Semanal'!EE16:EI16) -> -171.16042 | AE14: =-SUM('Motor Semanal'!EJ16:EN16) -> -193.79581 | AF14: =-SUM('Motor Semanal'!EO16:ES16) -> -150.60941 | AG14: =-SUM('Motor Semanal'!ET16:EX16) -> -195.88313 | AH14: =-SUM('Motor Semanal'!EY16:FC16) -> -217.43163 | AI14: =-SUM('Motor Semanal'!FD16:FH16) -> -207.63584 | AJ14: =-SUM('Motor Semanal'!FI16:FM16) -> -212.96937 | AK14: =-SUM('Motor Semanal'!FN16:FR16) -> -200.29816 | AL14: =-SUM('Motor Semanal'!FS16:FW16) -> -103.85236 | AM14: =-SUM('Motor Semanal'!FX16:GB16) -> -206.38913 | AN14: =-SUM('Motor Semanal'!GC16:GF16) -> -173.87797 | AO14: =-SUM('Motor Semanal'!GG16:GK16) -> -187.38559 | AP14: =-SUM('Motor Semanal'!GL16:GP16) -> -181.27444 | AQ14: =-SUM('Motor Semanal'!GQ16:GU16) -> -205.24738 | AR14: =-SUM('Motor Semanal'!GV16:GZ16) -> -159.50906 | AS14: =-SUM('Motor Semanal'!HA16:HE16) -> -207.45804 | AT14: =-SUM('Motor Semanal'!HF16:HJ16) -> -230.27986 | AU14: =-SUM('Motor Semanal'!HK16:HO16) -> -219.90523 | AV14: =-SUM('Motor Semanal'!HP16:HT16) -> -225.55392 | AW14: =-SUM('Motor Semanal'!HU16:HY16) -> -212.13396 | AX14: =-SUM('Motor Semanal'!HZ16:ID16) -> -109.98909 | AY14: =-SUM('Motor Semanal'!IE16:II16) -> -215.47026 | AZ14: =-SUM('Motor Semanal'!IJ16:IM16) -> -181.5286 | BA14: =-SUM('Motor Semanal'!IN16:IR16) -> -195.63056 | BB14: =-SUM('Motor Semanal'!IS16:IW16) -> -189.25052 | BC14: =-SUM('Motor Semanal'!IX16:JB16) -> -214.27827 | BD14: =-SUM('Motor Semanal'!JC16:JG16) -> -166.52746 | BE14: =-SUM('Motor Semanal'!JH16:JL16) -> -216.5862 | BF14: =-SUM('Motor Semanal'!JM16:JQ16) -> -240.41218 | BG14: =-SUM('Motor Semanal'!JR16:JV16) -> -229.58106 | BH14: =-SUM('Motor Semanal'!JW16:KA16) -> -235.4783 | BI14: =-SUM('Motor Semanal'!KB16:KF16) -> -221.46786 | BJ14: =-SUM('Motor Semanal'!KG16:KK16) -> -114.82861 | BK14: =-SUM('Motor Semanal'!KL16:KP16) -> -221.21613 | BL14: =-SUM('Motor Semanal'!KQ16:KT16) -> -186.36936 | BM14: =-SUM('Motor Semanal'!KU16:KY16) -> -200.84737 | BN14: =-SUM('Motor Semanal'!KZ16:LD16) -> -194.2972 | BO14: =-SUM('Motor Semanal'!LE16:LI16) -> -219.99235 | BP14: =-SUM('Motor Semanal'!LJ16:LN16) -> -170.96819 | BQ14: =-SUM('Motor Semanal'!LO16:LS16) -> -222.36183 | BR14: =-SUM('Motor Semanal'!LT16:LX16) -> -246.82317 | BS14: =-SUM('Motor Semanal'!LY16:MC16) -> -235.70322 | BT14: =-SUM('Motor Semanal'!MD16:MH16) -> -241.75772 | BU14: =-SUM('Motor Semanal'!MI16:MM16) -> -227.37367 | BV14: =-SUM('Motor Semanal'!MN16:MR16) -> -117.89071 | BW14: =-SUM('Motor Semanal'!MS16:MW16) -> -220.66309 | BX14: =-SUM('Motor Semanal'!MX16:NB16) -> -185.90344 | BY14: =-SUM('Motor Semanal'!NC16:NG16) -> -200.34526 | BZ14: =-SUM('Motor Semanal'!NH16:NL16) -> -193.81145 | CA14: =-SUM('Motor Semanal'!NM16:NQ16) -> -219.44237 | CB14: =-SUM('Motor Semanal'!NR16:NV16) -> -170.54077 | CC14: =-SUM('Motor Semanal'!NW16:OA16) -> -221.80592 | CD14: =-SUM('Motor Semanal'!OB16:OF16) -> -246.20611 | CE14: =-SUM('Motor Semanal'!OG16:OK16) -> -235.11396 | CF14: =-SUM('Motor Semanal'!OL16:OP16) -> -241.15332 | CG14: =-SUM('Motor Semanal'!OQ16:OU16) -> -226.80523 | CH14: =-SUM('Motor Semanal'!OV16:OZ16) -> -117.59598 | CI14: =-SUM('Motor Semanal'!PA16:PE16) -> -215.61936 | CJ14: =-SUM('Motor Semanal'!PF16:PI16) -> -181.65422 | CK14: =-SUM('Motor Semanal'!PJ16:PN16) -> -195.76594 | CL14: =-SUM('Motor Semanal'!PO16:PS16) -> -189.38148 | CM14: =-SUM('Motor Semanal'!PT16:PX16) -> -214.42655 | CN14: =-SUM('Motor Semanal'!PY16:QC16) -> -166.6427 | CO14: =-SUM('Motor Semanal'!QD16:QH16) -> -216.73607 | CP14: =-SUM('Motor Semanal'!QI16:QM16) -> -240.57854 | CQ14: =-SUM('Motor Semanal'!QN16:QR16) -> -229.73993 | CR14: =-SUM('Motor Semanal'!QS16:QW16) -> -235.64125 | CS14: =-SUM('Motor Semanal'!QX16:RB16) -> -221.62111 | CT14: =-SUM('Motor Semanal'!RC16:RG16) -> -114.90807 | CU14: =-SUM('Motor Semanal'!RH16:RL16) -> -204.83839 | CV14: =-SUM('Motor Semanal'!RM16:RP16) -> -172.57151 | CW14: =-SUM('Motor Semanal'!RQ16:RU16) -> -185.97764 | CX14: =-SUM('Motor Semanal'!RV16:RZ16) -> -179.9124 | CY14: =-SUM('Motor Semanal'!SA16:SE16) -> -203.70522 | CZ14: =-SUM('Motor Semanal'!SF16:SJ16) -> -158.31056 | DA14: =-SUM('Motor Semanal'!SK16:SO16) -> -205.89927 | DB14: =-SUM('Motor Semanal'!SP16:ST16) -> -228.54961 | DC14: =-SUM('Motor Semanal'!SU16:SY16) -> -218.25293 | DD14: =-SUM('Motor Semanal'!SZ16:TD16) -> -223.85919 | DE14: =-SUM('Motor Semanal'!TE16:TI16) -> -210.54006 | DF14: =-SUM('Motor Semanal'!TJ16:TN16) -> -109.16267
A15: TOTAL INGRESOS OPERATIVOS | B15: Suma de las 4 líneas | C15: =SUM(C11:C14) -> 9123.7929 | D15: =SUM(D11:D14) -> 8063.8112 | E15: =SUM(E11:E14) -> 12136.725 | F15: =SUM(F11:F14) -> 11308.486 | G15: =SUM(G11:G14) -> 11715.243 | H15: =SUM(H11:H14) -> 10279.529 | I15: =SUM(I11:I14) -> 11371.632 | J15: =SUM(J11:J14) -> 14805.95 | ... DF15: =SUM(DF11:DF14) -> 26919.687
A17: 2. EGRESOS OPERATIVOS
A18: Compras de mercadería | B18: Ventas de 2 meses después × fila 60 | C18: =E10*C60 -> 9740.0794 | D18: =F10*D60 -> 9422.429 | E18: =G10*E60 -> 10668.514 | F18: =H10*F60 -> 8291.0906 | G18: =I10*G60 -> 10783.421 | H18: =J10*H60 -> 11969.672 | I18: =K10*I60 -> 11430.411 | J18: =L10*J60 -> 11724.024 | ... DF18: =DH10*DF60 -> 32069.756
